Workbook

Sheet Daily Expenses
A1: ID | B1: Date (YYYY-MM-DD) | C1: Category | D1: Title / Description | E1: Amount ($) | F1: Week Num | G1: Month | H1: Year
A2: 1 | B2: 46305 | C2: Food | D2: Groceries | E2: 45.5 | F2: =IF(B2="","",ISOWEEKNUM(IF(ISNUMBER(B2),B2,DATEVALUE(B2)))) | G2: =IF(B2="","",TEXT(IF(ISNUMBER(B2),B2,DATEVALUE(B2)),"yyyy-mm")) | H2: =IF(B2="","",YEAR(IF(ISNUMBER(B2),B2,DATEVALUE(B2))))
A3: 2 | B3: 46306 | C3: Transport | D3: Metro Pass | E3: 20 | F3: =IF(B3="","",ISOWEEKNUM(IF(ISNUMBER(B3),B3,DATEVALUE(B3)))) | G3: =IF(B3="","",TEXT(IF(ISNUMBER(B3),B3,DATEVALUE(B3)),"yyyy-mm")) | H3: =IF(B3="","",YEAR(IF(ISNUMBER(B3),B3,DATEVALUE(B3))))
A4: 3 | B4: 46307 | C4: Food | D4: Coffee with Friends | E4: 12.75 | F4: =IF(B4="","",ISOWEEKNUM(IF(ISNUMBER(B4),B4,DATEVALUE(B4)))) | G4: =IF(B4="","",TEXT(IF(ISNUMBER(B4),B4,DATEVALUE(B4)),"yyyy-mm")) | H4: =IF(B4="","",YEAR(IF(ISNUMBER(B4),B4,DATEVALUE(B4))))
A5: 4 | B5: 46308 | C5: Bills | D5: Internet Bill | E5: 55 | F5: =IF(B5="","",ISOWEEKNUM(IF(ISNUMBER(B5),B5,DATEVALUE(B5)))) | G5: =IF(B5="","",TEXT(IF(ISNUMBER(B5),B5,DATEVALUE(B5)),"yyyy-mm")) | H5: =IF(B5="","",YEAR(IF(ISNUMBER(B5),B5,DATEVALUE(B5))))
F6: =IF(B6="","",ISOWEEKNUM(IF(ISNUMBER(B6),B6,DATEVALUE(B6)))) | G6: =IF(B6="","",TEXT(IF(ISNUMBER(B6),B6,DATEVALUE(B6)),"yyyy-mm")) | H6: =IF(B6="","",YEAR(IF(ISNUMBER(B6),B6,DATEVALUE(B6))))
F7: =IF(B7="","",ISOWEEKNUM(IF(ISNUMBER(B7),B7,DATEVALUE(B7)))) | G7: =IF(B7="","",TEXT(IF(ISNUMBER(B7),B7,DATEVALUE(B7)),"yyyy-mm")) | H7: =IF(B7="","",YEAR(IF(ISNUMBER(B7),B7,DATEVALUE(B7))))
F8: =IF(B8="","",ISOWEEKNUM(IF(ISNUMBER(B8),B8,DATEVALUE(B8)))) | G8: =IF(B8="","",TEXT(IF(ISNUMBER(B8),B8,DATEVALUE(B8)),"yyyy-mm")) | H8: =IF(B8="","",YEAR(IF(ISNUMBER(B8),B8,DATEVALUE(B8))))
F9: =IF(B9="","",ISOWEEKNUM(IF(ISNUMBER(B9),B9,DATEVALUE(B9)))) | G9: =IF(B9="","",TEXT(IF(ISNUMBER(B9),B9,DATEVALUE(B9)),"yyyy-mm")) | H9: =IF(B9="","",YEAR(IF(ISNUMBER(B9),B9,DATEVALUE(B9))))
F10: =IF(B10="","",ISOWEEKNUM(IF(ISNUMBER(B10),B10,DATEVALUE(B10)))) | G10: =IF(B10="","",TEXT(IF(ISNUMBER(B10),B10,DATEVALUE(B10)),"yyyy-mm")) | H10: =IF(B10="","",YEAR(IF(ISNUMBER(B10),B10,DATEVALUE(B10))))
F11: =IF(B11="","",ISOWEEKNUM(IF(ISNUMBER(B11),B11,DATEVALUE(B11)))) | G11: =IF(B11="","",TEXT(IF(ISNUMBER(B11),B11,DATEVALUE(B11)),"yyyy-mm")) | H11: =IF(B11="","",YEAR(IF(ISNUMBER(B11),B11,DATEVALUE(B11))))
F12: =IF(B12="","",ISOWEEKNUM(IF(ISNUMBER(B12),B12,DATEVALUE(B12)))) | G12: =IF(B12="","",TEXT(IF(ISNUMBER(B12),B12,DATEVALUE(B12)),"yyyy-mm")) | H12: =IF(B12="","",YEAR(IF(ISNUMBER(B12),B12,DATEVALUE(B12))))
F13: =IF(B13="","",ISOWEEKNUM(IF(ISNUMBER(B13),B13,DATEVALUE(B13)))) | G13: =IF(B13="","",TEXT(IF(ISNUMBER(B13),B13,DATEVALUE(B13)),"yyyy-mm")) | H13: =IF(B13="","",YEAR(IF(ISNUMBER(B13),B13,DATEVALUE(B13))))
F14: =IF(B14="","",ISOWEEKNUM(IF(ISNUMBER(B14),B14,DATEVALUE(B14)))) | G14: =IF(B14="","",TEXT(IF(ISNUMBER(B14),B14,DATEVALUE(B14)),"yyyy-mm")) | H14: =IF(B14="","",YEAR(IF(ISNUMBER(B14),B14,DATEVALUE(B14))))
F15: =IF(B15="","",ISOWEEKNUM(IF(ISNUMBER(B15),B15,DATEVALUE(B15)))) | G15: =IF(B15="","",TEXT(IF(ISNUMBER(B15),B15,DATEVALUE(B15)),"yyyy-mm")) | H15: =IF(B15="","",YEAR(IF(ISNUMBER(B15),B15,DATEVALUE(B15))))
F16: =IF(B16="","",ISOWEEKNUM(IF(ISNUMBER(B16),B16,DATEVALUE(B16)))) | G16: =IF(B16="","",TEXT(IF(ISNUMBER(B16),B16,DATEVALUE(B16)),"yyyy-mm")) | H16: =IF(B16="","",YEAR(IF(ISNUMBER(B16),B16,DATEVALUE(B16))))
F17: =IF(B17="","",ISOWEEKNUM(IF(ISNUMBER(B17),B17,DATEVALUE(B17)))) | G17: =IF(B17="","",TEXT(IF(ISNUMBER(B17),B17,DATEVALUE(B17)),"yyyy-mm")) | H17: =IF(B17="","",YEAR(IF(ISNUMBER(B17),B17,DATEVALUE(B17))))
... F200: =IF(B200="","",ISOWEEKNUM(IF(ISNUMBER(B200),B200,DATEVALUE(B200)))) | G200: =IF(B200="","",TEXT(IF(ISNUMBER(B200),B200,DATEVALUE(B200)),"yyyy-mm")) | H200: =IF(B200="","",YEAR(IF(ISNUMBER(B200),B200,DATEVALUE(B200))))

Sheet Summary & Analytics
A1: 📊 PERSONAL EXPENSE TRACKER - SUMMARY & ANALYTICS
A2: Live formulas automatically calculating total weekly, monthly, and yearly expenses as you enter daily records
B4: 💰 Total Spending | C4: 📝 Total Transactions | D4: 📅 This Week's Total | E4: 🗓️ This Month's Total | F4: 📆 This Year's Total
B5: =SUM('Daily Expenses'!E2:E1000) | C5: =COUNTA('Daily Expenses'!B2:B1000) | D5: =SUMIFS('Daily Expenses'!E2:E1000, 'Daily Expenses'!F2:F1000, ISOWEEKNUM(TODAY())) | E5: =SUMIFS('Daily Expenses'!E2:E1000, 'Daily Expenses'!G2:G1000, TEXT(TODAY(),"yyyy-mm")) | F5: =SUMIFS('Daily Expenses'!E2:E1000, 'Daily Expenses'!H2:H1000, YEAR(TODAY()))
A8: 🗓️ MONTHLY EXPENSES (2026) | E8: 📅 WEEKLY EXPENSES (Weeks 1 to 52)
A9: Month Key | B9: Month Name | C9: Total Spent ($) | E9: Week # | F9: Week Label | G9: Total Spent ($)
A10: 2026-01 | B10: January 2026 | C10: =SUMIF('Daily Expenses'!$G$2:$G$1000, A10, 'Daily Expenses'!$E$2:$E$1000) | E10: 1 | F10: Week 01 | G10: =SUMIF('Daily Expenses'!$F$2:$F$1000, E10, 'Daily Expenses'!$E$2:$E$1000)
A11: 2026-02 | B11: February 2026 | C11: =SUMIF('Daily Expenses'!$G$2:$G$1000, A11, 'Daily Expenses'!$E$2:$E$1000) | E11: 2 | F11: Week 02 | G11: =SUMIF('Daily Expenses'!$F$2:$F$1000, E11, 'Daily Expenses'!$E$2:$E$1000)
A12: 2026-03 | B12: March 2026 | C12: =SUMIF('Daily Expenses'!$G$2:$G$1000, A12, 'Daily Expenses'!$E$2:$E$1000) | E12: 3 | F12: Week 03 | G12: =SUMIF('Daily Expenses'!$F$2:$F$1000, E12, 'Daily Expenses'!$E$2:$E$1000)
A13: 2026-04 | B13: April 2026 | C13: =SUMIF('Daily Expenses'!$G$2:$G$1000, A13, 'Daily Expenses'!$E$2:$E$1000) | E13: 4 | F13: Week 04 | G13: =SUMIF('Daily Expenses'!$F$2:$F$1000, E13, 'Daily Expenses'!$E$2:$E$1000)
A14: 2026-05 | B14: May 2026 | C14: =SUMIF('Daily Expenses'!$G$2:$G$1000, A14, 'Daily Expenses'!$E$2:$E$1000) | E14: 5 | F14: Week 05 | G14: =SUMIF('Daily Expenses'!$F$2:$F$1000, E14, 'Daily Expenses'!$E$2:$E$1000)
A15: 2026-06 | B15: June 2026 | C15: =SUMIF('Daily Expenses'!$G$2:$G$1000, A15, 'Daily Expenses'!$E$2:$E$1000) | E15: 6 | F15: Week 06 | G15: =SUMIF('Daily Expenses'!$F$2:$F$1000, E15, 'Daily Expenses'!$E$2:$E$1000)
A16: 2026-07 | B16: July 2026 | C16: =SUMIF('Daily Expenses'!$G$2:$G$1000, A16, 'Daily Expenses'!$E$2:$E$1000) | E16: 7 | F16: Week 07 | G16: =SUMIF('Daily Expenses'!$F$2:$F$1000, E16, 'Daily Expenses'!$E$2:$E$1000)
A17: 2026-08 | B17: August 2026 | C17: =SUMIF('Daily Expenses'!$G$2:$G$1000, A17, 'Daily Expenses'!$E$2:$E$1000) | E17: 8 | F17: Week 08 | G17: =SUMIF('Daily Expenses'!$F$2:$F$1000, E17, 'Daily Expenses'!$E$2:$E$1000)
A18: 2026-09 | B18: September 2026 | C18: =SUMIF('Daily Expenses'!$G$2:$G$1000, A18, 'Daily Expenses'!$E$2:$E$1000) | E18: 9 | F18: Week 09 | G18: =SUMIF('Daily Expenses'!$F$2:$F$1000, E18, 'Daily Expenses'!$E$2:$E$1000)
A19: 2026-10 | B19: October 2026 | C19: =SUMIF('Daily Expenses'!$G$2:$G$1000, A19, 'Daily Expenses'!$E$2:$E$1000) | E19: 10 | F19: Week 10 | G19: =SUMIF('Daily Expenses'!$F$2:$F$1000, E19, 'Daily Expenses'!$E$2:$E$1000)
A20: 2026-11 | B20: November 2026 | C20: =SUMIF('Daily Expenses'!$G$2:$G$1000, A20, 'Daily Expenses'!$E$2:$E$1000) | E20: 11 | F20: Week 11 | G20: =SUMIF('Daily Expenses'!$F$2:$F$1000, E20, 'Daily Expenses'!$E$2:$E$1000)
A21: 2026-12 | B21: December 2026 | C21: =SUMIF('Daily Expenses'!$G$2:$G$1000, A21, 'Daily Expenses'!$E$2:$E$1000) | E21: 12 | F21: Week 12 | G21: =SUMIF('Daily Expenses'!$F$2:$F$1000, E21, 'Daily Expenses'!$E$2:$E$1000)
A22: Total Year | B22: All Months (2026) | C22: =SUM(C10:C21) | E22: 13 | F22: Week 13 | G22: =SUMIF('Daily Expenses'!$F$2:$F$1000, E22, 'Daily Expenses'!$E$2:$E$1000)
E23: 14 | F23: Week 14 | G23: =SUMIF('Daily Expenses'!$F$2:$F$1000, E23, 'Daily Expenses'!$E$2:$E$1000)
A24: 📆 YEARLY EXPENSES | E24: 15 | F24: Week 15 | G24: =SUMIF('Daily Expenses'!$F$2:$F$1000, E24, 'Daily Expenses'!$E$2:$E$1000)
A25: Year | B25: Description | C25: Total Spent ($) | E25: 16 | F25: Week 16 | G25: =SUMIF('Daily Expenses'!$F$2:$F$1000, E25, 'Daily Expenses'!$E$2:$E$1000)
A26: 2024 | B26: Past Year (2024) | C26: =SUMIF('Daily Expenses'!$H$2:$H$1000, A26, 'Daily Expenses'!$E$2:$E$1000) | E26: 17 | F26: Week 17 | G26: =SUMIF('Daily Expenses'!$F$2:$F$1000, E26, 'Daily Expenses'!$E$2:$E$1000)
A27: 2025 | B27: Previous Year (2025) | C27: =SUMIF('Daily Expenses'!$H$2:$H$1000, A27, 'Daily Expenses'!$E$2:$E$1000) | E27: 18 | F27: Week 18 | G27: =SUMIF('Daily Expenses'!$F$2:$F$1000, E27, 'Daily Expenses'!$E$2:$E$1000)
A28: 2026 | B28: Current Year (2026) | C28: =SUMIF('Daily Expenses'!$H$2:$H$1000, A28, 'Daily Expenses'!$E$2:$E$1000) | E28: 19 | F28: Week 19 | G28: =SUMIF('Daily Expenses'!$F$2:$F$1000, E28, 'Daily Expenses'!$E$2:$E$1000)
A29: 2027 | B29: Upcoming Year (2027) | C29: =SUMIF('Daily Expenses'!$H$2:$H$1000, A29, 'Daily Expenses'!$E$2:$E$1000) | E29: 20 | F29: Week 20 | G29: =SUMIF('Daily Expenses'!$F$2:$F$1000, E29, 'Daily Expenses'!$E$2:$E$1000)
A30: 2028 | B30: Future Year (2028) | C30: =SUMIF('Daily Expenses'!$H$2:$H$1000, A30, 'Daily Expenses'!$E$2:$E$1000) | E30: 21 | F30: Week 21 | G30: =SUMIF('Daily Expenses'!$F$2:$F$1000, E30, 'Daily Expenses'!$E$2:$E$1000)
E31: 22 | F31: Week 22 | G31: =SUMIF('Daily Expenses'!$F$2:$F$1000, E31, 'Daily Expenses'!$E$2:$E$1000)
E32: 23 | F32: Week 23 | G32: =SUMIF('Daily Expenses'!$F$2:$F$1000, E32, 'Daily Expenses'!$E$2:$E$1000)
A33: 🏷️ SPENDING BY CATEGORY | E33: 24 | F33: Week 24 | G33: =SUMIF('Daily Expenses'!$F$2:$F$1000, E33, 'Daily Expenses'!$E$2:$E$1000)
A34: Category | B34: % Share | C34: Total Spent ($) | E34: 25 | F34: Week 25 | G34: =SUMIF('Daily Expenses'!$F$2:$F$1000, E34, 'Daily Expenses'!$E$2:$E$1000)
A35: Food | B35: =IF($B$5>0, C35/$B$5, 0) | C35: =SUMIF('Daily Expenses'!$C$2:$C$1000, A35, 'Daily Expenses'!$E$2:$E$1000) | E35: 26 | F35: Week 26 | G35: =SUMIF('Daily Expenses'!$F$2:$F$1000, E35, 'Daily Expenses'!$E$2:$E$1000)
A36: Transport | B36: =IF($B$5>0, C36/$B$5, 0) | C36: =SUMIF('Daily Expenses'!$C$2:$C$1000, A36, 'Daily Expenses'!$E$2:$E$1000) | E36: 27 | F36: Week 27 | G36: =SUMIF('Daily Expenses'!$F$2:$F$1000, E36, 'Daily Expenses'!$E$2:$E$1000)
A37: Bills | B37: =IF($B$5>0, C37/$B$5, 0) | C37: =SUMIF('Daily Expenses'!$C$2:$C$1000, A37, 'Daily Expenses'!$E$2:$E$1000) | E37: 28 | F37: Week 28 | G37: =SUMIF('Daily Expenses'!$F$2:$F$1000, E37, 'Daily Expenses'!$E$2:$E$1000)
A38: Shopping | B38: =IF($B$5>0, C38/$B$5, 0) | C38: =SUMIF('Daily Expenses'!$C$2:$C$1000, A38, 'Daily Expenses'!$E$2:$E$1000) | E38: 29 | F38: Week 29 | G38: =SUMIF('Daily Expenses'!$F$2:$F$1000, E38, 'Daily Expenses'!$E$2:$E$1000)
A39: Entertainment | B39: =IF($B$5>0, C39/$B$5, 0) | C39: =SUMIF('Daily Expenses'!$C$2:$C$1000, A39, 'Daily Expenses'!$E$2:$E$1000) | E39: 30 | F39: Week 30 | G39: =SUMIF('Daily Expenses'!$F$2:$F$1000, E39, 'Daily Expenses'!$E$2:$E$1000)
A40: Health | B40: =IF($B$5>0, C40/$B$5, 0) | C40: =SUMIF('Daily Expenses'!$C$2:$C$1000, A40, 'Daily Expenses'!$E$2:$E$1000) | E40: 31 | F40: Week 31 | G40: =SUMIF('Daily Expenses'!$F$2:$F$1000, E40, 'Daily Expenses'!$E$2:$E$1000)
A41: Education | B41: =IF($B$5>0, C41/$B$5, 0) | C41: =SUMIF('Daily Expenses'!$C$2:$C$1000, A41, 'Daily Expenses'!$E$2:$E$1000) | E41: 32 | F41: Week 32 | G41: =SUMIF('Daily Expenses'!$F$2:$F$1000, E41, 'Daily Expenses'!$E$2:$E$1000)
A42: Other | B42: =IF($B$5>0, C42/$B$5, 0) | C42: =SUMIF('Daily Expenses'!$C$2:$C$1000, A42, 'Daily Expenses'!$E$2:$E$1000) | E42: 33 | F42: Week 33 | G42: =SUMIF('Daily Expenses'!$F$2:$F$1000, E42, 'Daily Expenses'!$E$2:$E$1000)
E43: 34 | F43: Week 34 | G43: =SUMIF('Daily Expenses'!$F$2:$F$1000, E43, 'Daily Expenses'!$E$2:$E$1000)
...
